<?xml version="1.0" ?>
<!-- =================================================================================== -->
<!-- |    This document was autogenerated by xacro from sda10f_uni_kin_ref_kin_macro_newKin.xacro | -->
<!-- |    EDITING THIS FILE BY HAND IS NOT RECOMMENDED                                 | -->
<!-- =================================================================================== -->
<robot name="sda10f" xmlns:xacro="http://ros.org/wiki/xacro">
  <!-- link list -->
  <link name="base_link">
    <visual>
      <geometry>
        <mesh filename="package://uniform_object_rearrangement/urdf/sda10f_description/meshes/sda10f/visual/motoman_base.stl"/>
      </geometry>
      <material name="blue">
        <color rgba="0 0 1 1"/>
      </material>
    </visual>
    <collision>
      <geometry>
        <mesh filename="package://uniform_object_rearrangement/urdf/sda10f_description/meshes/sda10f/collision/motoman_base.stl"/>
      </geometry>
      <material name="yellow">
        <color rgba="0 1 1 1"/>
      </material>
    </collision>
    <!-- <inertial> -->
      <!-- <mass value="0.00001"/> -->
      <!-- <mass value="0.0"/> -->
      <!-- <origin rpy="0 -0 0" xyz="0 0 0"/> -->
      <!-- <inertia ixx="1" ixy="0" ixz="0" iyy="1" iyz="0" izz="1"/> -->
    <!-- </inertial> -->
  </link>

  <!-- joint list -->
  <joint name="torso_joint_b1" type="revolute">
  <!-- <joint name="torso_joint_b1" type="fixed"> -->
    <parent link="base_link"/>
    <child link="torso_link_b1"/>
    <origin rpy="0 0 0" xyz="0.09257 0 0.877"/>
    <axis xyz="0 0 1"/>
    <limit effort="100" lower="-1.58" upper="1.58" velocity="2.26"/>
    <!-- <limit effort="100" lower="-2.9570" upper="2.9570" velocity="2.26"/> -->
    <!-- <limit effort="100" lower="-0.0001" upper="0.0001" velocity="2.26"/> -->
  </joint>
  <!-- end of joint list -->

  <link name="torso_link_b1">
    <visual>
      <origin rpy="0 0 0" xyz="0 0 0"/>
      <geometry>
        <mesh filename="package://uniform_object_rearrangement/urdf/sda10f_description/meshes/sda10f/visual/motoman_axis_b1.stl"/>
      </geometry>
      <material name="silver">
        <color rgba="0.8 0.8 0.8 1"/>
      </material>
    </visual>
    <collision>
      <origin rpy="0 0 0" xyz="0 0 0"/>
      <geometry>
        <mesh filename="package://uniform_object_rearrangement/urdf/sda10f_description/meshes/sda10f/collision/motoman_axis_b1.stl"/>
        <!-- <mesh filename="sda10f_description/meshes/sda10f/collision/motoman_axis_b1.stl"/> -->
      </geometry>
      <material name="yellow"/>
    </collision>
  </link>

  <link name="arm_left_link_1_s">
    <visual>
      <origin rpy="0 0 0" xyz="0 0 0"/>
      <geometry>
        <mesh filename="package://uniform_object_rearrangement/urdf/sda10f_description/meshes/sda10f/visual/motoman_axis_s.stl"/>
        <!-- <mesh filename="sda10f_description/meshes/sda10f/visual/motoman_axis_s.stl"/> -->
      </geometry>
      <material name="blue">
        <color rgba="0.65 0.65 0.65 1"/>
      </material>
    </visual>
    <collision>
      <origin rpy="0 0 0" xyz="0 0 0"/>
      <geometry>
        <mesh filename="package://uniform_object_rearrangement/urdf/sda10f_description/meshes/sda10f/collision/motoman_axis_s.stl"/>
        <!-- <mesh filename="sda10f_description/meshes/sda10f/collision/motoman_axis_s.stl"/> -->
      </geometry>
      <material name="yellow"/>
    </collision>
  </link>
  <link name="arm_left_link_2_l">
    <visual>
      <origin rpy="0 0 0" xyz="0 0 0"/>
      <geometry>
        <mesh filename="package://uniform_object_rearrangement/urdf/sda10f_description/meshes/sda10f/visual/motoman_axis_l.stl"/>
        <!-- <mesh filename="sda10f_description/meshes/sda10f/visual/motoman_axis_l.stl"/> -->
      </geometry>
      <material name="silver"/>
    </visual>
    <collision>
      <origin rpy="0 0 0" xyz="0 0 0"/>
      <geometry>
        <mesh filename="package://uniform_object_rearrangement/urdf/sda10f_description/meshes/sda10f/collision/motoman_axis_l.stl"/>
        <!-- <mesh filename="sda10f_description/meshes/sda10f/collision/motoman_axis_l.stl"/> -->
      </geometry>
      <material name="yellow"/>
    </collision>
  </link>
  <link name="arm_left_link_3_e">
    <visual>
      <origin rpy="0 0 0" xyz="0 0 0"/>
      <geometry>
        <mesh filename="package://uniform_object_rearrangement/urdf/sda10f_description/meshes/sda10f/visual/motoman_axis_e.stl"/>
        <!-- <mesh filename="sda10f_description/meshes/sda10f/visual/motoman_axis_e.stl"/> -->
      </geometry>
      <material name="blue"/>
    </visual>
    <collision>
      <origin rpy="0 0 0" xyz="0 0 0"/>
      <geometry>
        <mesh filename="package://uniform_object_rearrangement/urdf/sda10f_description/meshes/sda10f/collision/motoman_axis_e.stl"/>
        <!-- <mesh filename="sda10f_description/meshes/sda10f/collision/motoman_axis_e.stl"/> -->
      </geometry>
      <material name="yellow"/>
    </collision>
  </link>
  <link name="arm_left_link_4_u">
    <visual>
      <origin rpy="0 0 0" xyz="0 0 0"/>
      <geometry>
        <mesh filename="package://uniform_object_rearrangement/urdf/sda10f_description/meshes/sda10f/visual/motoman_axis_u.stl"/>
        <!-- <mesh filename="sda10f_description/meshes/sda10f/visual/motoman_axis_u.stl"/> -->
      </geometry>
      <material name="silver"/>
    </visual>
    <collision>
      <origin rpy="0 0 0" xyz="0 0 0"/>
      <geometry>
        <mesh filename="package://uniform_object_rearrangement/urdf/sda10f_description/meshes/sda10f/collision/motoman_axis_u.stl"/>
        <!-- <mesh filename="sda10f_description/meshes/sda10f/collision/motoman_axis_u.stl"/> -->
      </geometry>
      <material name="yellow"/>
    </collision>
  </link>
  <link name="arm_left_link_5_r">
    <visual>
      <origin rpy="0 0 0" xyz="0 0 0"/>
      <geometry>
        <mesh filename="package://uniform_object_rearrangement/urdf/sda10f_description/meshes/sda10f/visual/motoman_axis_r.stl"/>
        <!-- <mesh filename="sda10f_description/meshes/sda10f/visual/motoman_axis_r.stl"/> -->
      </geometry>
      <material name="blue"/>
    </visual>
    <collision>
      <origin rpy="0 0 0" xyz="0 0 0"/>
      <geometry>
        <mesh filename="package://uniform_object_rearrangement/urdf/sda10f_description/meshes/sda10f/collision/motoman_axis_r.stl"/>
        <!-- <mesh filename="sda10f_description/meshes/sda10f/collision/motoman_axis_r.stl"/> -->
      </geometry>
      <material name="yellow"/>
    </collision>
  </link>
  <link name="arm_left_link_6_b">
    <visual>
      <origin rpy="0 0 0" xyz="0 0 0"/>
      <geometry>
        <mesh filename="package://uniform_object_rearrangement/urdf/sda10f_description/meshes/sda10f/visual/motoman_axis_b.stl"/>
        <!-- <mesh filename="sda10f_description/meshes/sda10f/visual/motoman_axis_b.stl"/> -->
      </geometry>
      <material name="silver"/>
    </visual>
    <collision>
      <origin rpy="0 0 0" xyz="0 0 0"/>
      <geometry>
        <mesh filename="package://uniform_object_rearrangement/urdf/sda10f_description/meshes/sda10f/collision/motoman_axis_b.stl"/>
        <!-- <mesh filename="sda10f_description/meshes/sda10f/collision/motoman_axis_b.stl"/> -->
      </geometry>
      <material name="yellow"/>
    </collision>
  </link>
  <link name="arm_left_link_7_t">
    <visual>
      <geometry>
        <mesh filename="package://uniform_object_rearrangement/urdf/sda10f_description/meshes/sda10f/visual/motoman_axis_t.stl"/>
        <!-- <mesh filename="sda10f_description/meshes/sda10f/visual/motoman_axis_t.stl"/> -->
      </geometry>
      <material name="blue"/>
    </visual>
    <collision>
      <geometry>
        <mesh filename="package://uniform_object_rearrangement/urdf/sda10f_description/meshes/sda10f/collision/motoman_axis_t.stl"/>
        <!-- <mesh filename="sda10f_description/meshes/sda10f/collision/motoman_axis_t.stl"/> -->
      </geometry>
      <material name="yellow"/>
    </collision>
  </link>
  <link name="arm_left_link_tool0"/>

  <joint name="arm_left_joint_1_s" type="revolute">
    <parent link="torso_link_b1"/>
    <child link="arm_left_link_1_s"/>
     <origin rpy="1.57 0 0.0" xyz="0.09996 0.0375 0.32214"/>
    <axis xyz="0 0 -1.0"/>
    <limit effort="0" lower="-3.13" upper="3.13" velocity="2.95"/>
    <!-- <dynamics damping="3.5"/> -->
  </joint>
  <joint name="arm_left_joint_2_l" type="revolute">
    <parent link="arm_left_link_1_s"/>
    <child link="arm_left_link_2_l"/>
    <origin rpy="-1.57 0 0" xyz="0 0.0427 -0.2255"/>
    <axis xyz="0 0 -1.0"/>
    <limit effort="0" lower="-1.90" upper="1.90" velocity="2.95"/>
    <!-- <dynamics damping="3.5"/> -->
  </joint>
  <joint name="arm_left_joint_3_e" type="revolute">
    <parent link="arm_left_link_2_l"/>
    <child link="arm_left_link_3_e"/>
    <origin rpy="1.57 0 0" xyz="0 0.1790 -0.0454"/>
    <axis xyz="0 0 -1.0"/>
    <limit effort="0" lower="-2.95" upper="2.95" velocity="2.95"/>
    <!-- <dynamics damping="3.5"/> -->
  </joint>
  <joint name="arm_left_joint_4_u" type="revolute">
    <parent link="arm_left_link_3_e"/>
    <child link="arm_left_link_4_u"/>
    <origin rpy="-1.57 0 0" xyz="0 -0.0175 -0.181"/>
    <axis xyz="0 0 1"/>
    <limit effort="0" lower="-2.36" upper="2.36" velocity="2.95"/>
    <!-- <dynamics damping="3.5"/> -->
  </joint>
  <joint name="arm_left_joint_5_r" type="revolute">
    <parent link="arm_left_link_4_u"/>
    <child link="arm_left_link_5_r"/>
    <origin rpy="1.57 0 0" xyz="0 0.2036 0.0155"/>
    <axis xyz="0 0 1"/>
    <limit effort="0" lower="-3.13" upper="3.13" velocity="3.48"/>
    <!-- <dynamics damping="3.5"/> -->
  </joint>
  <joint name="arm_left_joint_6_b" type="revolute">
    <parent link="arm_left_link_5_r"/>
    <child link="arm_left_link_6_b"/>
    <origin rpy="-1.57 0 0" xyz="0 0.0130 -0.155"/>
    <axis xyz="0 0 1"/>
    <limit effort="0" lower="-1.90" upper="1.90" velocity="3.48"/>
    <!-- <dynamics damping="3.5"/> -->
  </joint>
  <joint name="arm_left_joint_7_t" type="revolute">
    <parent link="arm_left_link_6_b"/>
    <child link="arm_left_link_7_t"/>
     <origin rpy="1.57 0 0" xyz="0 0.144 -0.015"/>
    <axis xyz="0 0 1"/>
    <limit effort="0" lower="-3.13" upper="3.13" velocity="6.97"/>
    <!-- <dynamics damping="3.5"/> -->
  </joint>
  <joint name="arm_left_joint_tool0" type="fixed">
    <!-- the following line is modified by Rui-->
    <origin rpy="0 0 -3.13" xyz="0 0 -0.09"/>
    <!-- <origin rpy="0 0 -3.13" xyz="0 0 -0.07"/> -->
    <!-- <origin rpy="0 0 -3.13" xyz="0 0 -0.025"/> -->
    <!-- <origin rpy="0 0 -3.13" xyz="0 0 -0.0325"/> -->
    <!-- <origin rpy="0 0 -3.13" xyz="0 0 0.0"/> -->
    <parent link="arm_left_link_7_t"/>
    <child link="arm_left_link_tool0"/>
    <!-- <dynamics damping="3.5"/> -->
  </joint>
  <!-- end of joint list -->
  <link name="arm_right_link_1_s">
    <visual>
      <origin rpy="0 0 0" xyz="0 0 0"/>
      <geometry>
        <mesh filename="package://uniform_object_rearrangement/urdf/sda10f_description/meshes/sda10f/visual/motoman_axis_s.stl"/>
        <!-- <mesh filename="sda10f_description/meshes/sda10f/visual/motoman_axis_s.stl"/> -->
      </geometry>
      <material name="blue">
        <color rgba="0.65 0.65 0.65 1"/>
      </material>
    </visual>
    <collision>
      <origin rpy="0 0 0" xyz="0 0 0"/>
      <geometry>
        <mesh filename="package://uniform_object_rearrangement/urdf/sda10f_description/meshes/sda10f/collision/motoman_axis_s.stl"/>
        <!-- <mesh filename="sda10f_description/meshes/sda10f/collision/motoman_axis_s.stl"/> -->
      </geometry>
      <material name="yellow"/>
    </collision>
  </link>
  <link name="arm_right_link_2_l">
    <visual>
      <origin rpy="0 0 0" xyz="0 0 0"/>
      <geometry>
        <mesh filename="package://uniform_object_rearrangement/urdf/sda10f_description/meshes/sda10f/visual/motoman_axis_l.stl"/>
        <!-- <mesh filename="sda10f_description/meshes/sda10f/visual/motoman_axis_l.stl"/> -->
      </geometry>
      <material name="silver"/>
    </visual>
    <collision>
      <origin rpy="0 0 0" xyz="0 0 0"/>
      <geometry>
        <mesh filename="package://uniform_object_rearrangement/urdf/sda10f_description/meshes/sda10f/collision/motoman_axis_l.stl"/>
        <!-- <mesh filename="sda10f_description/meshes/sda10f/collision/motoman_axis_l.stl"/> -->
      </geometry>
      <material name="yellow"/>
    </collision>
  </link>
  <link name="arm_right_link_3_e">
    <visual>
      <origin rpy="0 0 0" xyz="0 0 0"/>
      <geometry>
        <mesh filename="package://uniform_object_rearrangement/urdf/sda10f_description/meshes/sda10f/visual/motoman_axis_e.stl"/>
        <!-- <mesh filename="sda10f_description/meshes/sda10f/visual/motoman_axis_e.stl"/> -->
      </geometry>
      <material name="blue"/>
    </visual>
    <collision>
      <origin rpy="0 0 0" xyz="0 0 0"/>
      <geometry>
        <mesh filename="package://uniform_object_rearrangement/urdf/sda10f_description/meshes/sda10f/collision/motoman_axis_e.stl"/>
        <!-- <mesh filename="sda10f_description/meshes/sda10f/collision/motoman_axis_e.stl"/> -->
      </geometry>
      <material name="yellow"/>
    </collision>
  </link>
  <link name="arm_right_link_4_u">
    <visual>
      <origin rpy="0 0 0" xyz="0 0 0"/>
      <geometry>
        <mesh filename="package://uniform_object_rearrangement/urdf/sda10f_description/meshes/sda10f/visual/motoman_axis_u.stl"/>
        <!-- <mesh filename="sda10f_description/meshes/sda10f/visual/motoman_axis_u.stl"/> -->
      </geometry>
      <material name="silver"/>
    </visual>
    <collision>
      <origin rpy="0 0 0" xyz="0 0 0"/>
      <geometry>
        <mesh filename="package://uniform_object_rearrangement/urdf/sda10f_description/meshes/sda10f/collision/motoman_axis_u.stl"/>
        <!-- <mesh filename="sda10f_description/meshes/sda10f/collision/motoman_axis_u.stl"/> -->
      </geometry>
      <material name="yellow"/>
    </collision>
  </link>
  <link name="arm_right_link_5_r">
    <visual>
      <origin rpy="0 0 0" xyz="0 0 0"/>
      <geometry>
        <mesh filename="package://uniform_object_rearrangement/urdf/sda10f_description/meshes/sda10f/visual/motoman_axis_r.stl"/>
        <!-- <mesh filename="sda10f_description/meshes/sda10f/visual/motoman_axis_r.stl"/> -->
      </geometry>
      <material name="blue"/>
    </visual>
    <collision>
      <origin rpy="0 0 0" xyz="0 0 0"/>
      <geometry>
        <mesh filename="package://uniform_object_rearrangement/urdf/sda10f_description/meshes/sda10f/collision/motoman_axis_r.stl"/>
        <!-- <mesh filename="sda10f_description/meshes/sda10f/collision/motoman_axis_r.stl"/> -->
      </geometry>
      <material name="yellow"/>
    </collision>
  </link>
  <link name="arm_right_link_6_b">
    <visual>
      <origin rpy="0 0 0" xyz="0 0 0"/>
      <geometry>
        <mesh filename="package://uniform_object_rearrangement/urdf/sda10f_description/meshes/sda10f/visual/motoman_axis_b.stl"/>
        <!-- <mesh filename="sda10f_description/meshes/sda10f/visual/motoman_axis_b.stl"/> -->
      </geometry>
      <material name="silver"/>
    </visual>
    <collision>
      <origin rpy="0 0 0" xyz="0 0 0"/>
      <geometry>
        <mesh filename="package://uniform_object_rearrangement/urdf/sda10f_description/meshes/sda10f/collision/motoman_axis_b.stl"/>
        <!-- <mesh filename="sda10f_description/meshes/sda10f/collision/motoman_axis_b.stl"/> -->
      </geometry>
      <material name="yellow"/>
    </collision>
  </link>
  <link name="arm_right_link_7_t">
    <visual>
      <geometry>
        <mesh filename="package://uniform_object_rearrangement/urdf/sda10f_description/meshes/sda10f/visual/motoman_axis_t.stl"/>
        <!-- <mesh filename="sda10f_description/meshes/sda10f/visual/motoman_axis_t.stl"/> -->
      </geometry>
      <material name="blue"/>
    </visual>
    <collision>
      <geometry>
        <mesh filename="package://uniform_object_rearrangement/urdf/sda10f_description/meshes/sda10f/collision/motoman_axis_t.stl"/>
        <!-- <mesh filename="sda10f_description/meshes/sda10f/collision/motoman_axis_t.stl"/> -->
      </geometry>
      <material name="yellow"/>
    </collision>
  </link>
  <link name="arm_right_link_tool0"/>

  <joint name="arm_right_joint_1_s" type="revolute">
    <parent link="torso_link_b1"/>
    <child link="arm_right_link_1_s"/>
    <origin rpy="1.57 0 -3.14" xyz="0.09996 -0.0375 0.32214"/>
    <axis xyz="0 0 1.0"/>
    <limit effort="0" lower="-3.13" upper="3.13" velocity="2.95"/>
  </joint>
  <joint name="arm_right_joint_2_l" type="revolute">
    <parent link="arm_right_link_1_s"/>
    <child link="arm_right_link_2_l"/>
    <origin rpy="-1.57 0 0" xyz="0 0.0427 -0.2255"/>
    <axis xyz="0 0 1.0"/>
    <limit effort="0" lower="-1.90" upper="1.90" velocity="2.95"/>
  </joint>
  <joint name="arm_right_joint_3_e" type="revolute">
    <parent link="arm_right_link_2_l"/>
    <child link="arm_right_link_3_e"/>
    <origin rpy="1.57 0 0" xyz="0 0.1790 -0.0454"/>
    <axis xyz="0 0 1.0"/>
    <limit effort="0" lower="-2.95" upper="2.95" velocity="2.95"/>
  </joint>
  <joint name="arm_right_joint_4_u" type="revolute">
    <parent link="arm_right_link_3_e"/>
    <child link="arm_right_link_4_u"/>
    <origin rpy="-1.57 0 0" xyz="0 -0.0175 -0.181"/>
    <axis xyz="0 0 -1"/>
    <limit effort="0" lower="-2.36" upper="2.36" velocity="2.95"/>
  </joint>
  <joint name="arm_right_joint_5_r" type="revolute">
    <parent link="arm_right_link_4_u"/>
    <child link="arm_right_link_5_r"/>
    <origin rpy="1.57 0 0" xyz="0 0.2036 0.0155"/>
    <axis xyz="0 0 -1"/>
    <limit effort="0" lower="-3.13" upper="3.13" velocity="3.48"/>
  </joint>
  <joint name="arm_right_joint_6_b" type="revolute">
    <parent link="arm_right_link_5_r"/>
    <child link="arm_right_link_6_b"/>
    <origin rpy="-1.57 0 0" xyz="0 0.0130 -0.155"/>
    <axis xyz="0 0 -1"/>
    <limit effort="0" lower="-1.90" upper="1.90" velocity="3.48"/>
  </joint>
  <joint name="arm_right_joint_7_t" type="revolute">
    <parent link="arm_right_link_6_b"/>
    <child link="arm_right_link_7_t"/>
    <origin rpy="1.57 0 0" xyz="0 0.144 -0.015"/>
    <axis xyz="0 0 -1"/>
    <limit effort="0" lower="-3.13" upper="3.13" velocity="6.97"/>
  </joint>
  <joint name="arm_right_joint_tool0" type="fixed">
    <!-- the following line is modified by Rui-->
    <origin rpy="0 0 -3.13" xyz="0 0 -0.025"/>
    <!-- <origin rpy="0 0 -3.13" xyz="0 0 -0.0325"/> -->
    <!-- <origin rpy="0 0 -3.13" xyz="0 0 0.0"/> origin -->
    <parent link="arm_right_link_7_t"/>
    <child link="arm_right_link_tool0"/>
  </joint>
  <!-- Links -->

  <joint name="motoman_left_joint_pre_ee" type="fixed">
    <parent link="arm_left_link_tool0"/>
    <child link="motoman_left_hand"/>
    <origin rpy="3.1416 0 0" xyz="0 0 0.0"/>
    <!-- <origin rpy="3.141 0 0" xyz="0 0 -0.07"/> -->
    <!-- <origin rpy="3.141 0 0" xyz="0 0 -0.028"/> -->
  </joint>
  <link name="motoman_left_hand">
    <visual>
      <geometry>
        <mesh filename="package://uniform_object_rearrangement/urdf/sda10f_description/meshes/sda10f/visual/vacuum_gripper_no_mouth.stl"/>
        <!-- <mesh filename="sda10f_description/meshes/sda10f/visual/vacuum_gripper_no_mouth.stl"/> -->
      </geometry>
      <material name="blue">
        <color rgba="0 0 1 1"/>
      </material>
    </visual>
    <collision>
      <geometry>
        <mesh filename="package://uniform_object_rearrangement/urdf/sda10f_description/meshes/sda10f/collision/vacuum_gripper_no_mouth.stl"/>
        <!-- <mesh filename="sda10f_description/meshes/sda10f/collision/vacuum_gripper_no_mouth.stl"/> -->
      </geometry>
      <material name="yellow">
        <color rgba="0 1 1 1"/>
      </material>
    </collision>
<!--     <visual>
      <geometry>
        <mesh filename="sda10f_description/meshes/sda10f/visual/baxter_suction2.stl"/>
      </geometry>
      <material name="blue">
        <color rgba="0 0 1 1"/>
      </material>
    </visual>
    <collision>
      <geometry>
        <mesh filename="sda10f_description/meshes/sda10f/collision/baxter_suction2.stl"/>
      </geometry>
      <material name="yellow">
        <color rgba="0 1 1 1"/>
      </material>
    </collision> -->

    </link>
  <joint name="motoman_left_joint_ee" type="fixed">
    <parent link="motoman_left_hand"/>
    <child link="motoman_left_ee"/>
    <origin rpy="0 0 0" xyz="0 0 0.3015"/>
    <!-- <origin rpy="0 0 0" xyz="0 0 0.068"/> -->
    <!-- <origin rpy="0 0 0" xyz="0 0 0"/> -->
  </joint>
  <link name="motoman_left_ee">
    </link>

  <joint name="motoman_right_joint_pre_ee" type="fixed">
    <parent link="arm_right_link_tool0"/>
    <!-- <child link="motoman_right_hand"/> -->
    <child link="robotiq_arg2f_base_link"/>
    <origin rpy="3.1416 0 1.57" xyz="0 0 0.0"/>
    <!-- <origin rpy="3.1416 0 0" xyz="0 0 0.0"/> -->
    <!-- <origin rpy="3.141 0 0" xyz="0 0 -0.035"/> -->
  </joint>

  <!-- <link name="motoman_right_hand">
    <visual>
      <geometry>
        <mesh filename="package://uniform_object_rearrangement/urdf/sda10f_description/meshes/sda10f/visual/modelO42.stl"/>
      </geometry>
      <material name="blue">
        <color rgba="0 0 1 1"/>
      </material>
    </visual>
    <collision>
      <geometry>
        <mesh filename="package://uniform_object_rearrangement/urdf/sda10f_description/meshes/sda10f/collision/modelO42.stl"/>
      </geometry>
      <material name="yellow">
        <color rgba="0 1 1 1"/>
      </material>
    </collision>
  </link> -->

  <joint name="motoman_right_joint_ee" type="fixed">
    <parent link="robotiq_arg2f_base_link"/>
    <!-- <parent link="motoman_right_hand"/> -->
    <child link="motoman_right_ee"/>
    <origin rpy="0 0 0" xyz="0 0 0.135"/>
  </joint>
  <link name="motoman_right_ee"></link>


  <link name="robotiq_arg2f_base_link">
    <inertial>
      <origin rpy="0 0 0" xyz="8.625E-08 -4.6583E-06 0.03145"/>
      <mass value="0.22652"/>
      <inertia ixx="0.00020005" ixy="-4.2442E-10" ixz="-2.9069E-10" iyy="0.00017832" iyz="-3.4402E-08" izz="0.00013478"/>
    </inertial>
    <visual>
      <origin rpy="0 0 0" xyz="0 0 0"/>
      <geometry>
        <mesh filename="package://uniform_object_rearrangement/urdf/robotiq_85/visual/robotiq_arg2f_85_base_link.dae" scale="0.001 0.001 0.001"/>
      </geometry>
      <material name="">
        <color rgba="0.1 0.1 0.1 1"/>
      </material>
    </visual>
    <collision>
      <origin rpy="0 0 0" xyz="0 0 0"/>
      <geometry>
        <mesh filename="package://uniform_object_rearrangement/urdf/robotiq_85/collision/robotiq_arg2f_base_link.stl"/>
      </geometry>
    </collision>
  </link>
  <link name="left_outer_knuckle">
    <!--<inertial>
        <origin xyz="-0.000200000000003065 0.0199435877845359 0.0292245259211331" rpy="0 0 0" />
        <mass value="0.00853198276973456" />
        <inertia ixx="2.89328108496468E-06" ixy="-1.57935047237397E-19" ixz="-1.93980378593255E-19" iyy="1.86719750325683E-06" iyz="-1.21858577871576E-06" izz="1.21905238907251E-06" />
        </inertial> -->
    <visual>
      <origin rpy="0 0 0" xyz="0 0 0"/>
      <geometry>
        <mesh filename="package://uniform_object_rearrangement/urdf/robotiq_85/visual/robotiq_arg2f_85_outer_knuckle.dae" scale="0.001 0.001 0.001"/>
      </geometry>
      <material name="">
        <color rgba="0.792156862745098 0.819607843137255 0.933333333333333 1"/>
      </material>
    </visual>
    <collision>
      <origin rpy="0 0 0" xyz="0 0 0"/>
      <geometry>
        <mesh filename="package://uniform_object_rearrangement/urdf/robotiq_85/collision/robotiq_arg2f_85_outer_knuckle.dae" scale="0.001 0.001 0.001"/>
      </geometry>
    </collision>
  </link>
  <link name="left_outer_finger">
    <!--<inertial>
        <origin xyz="0.00030115855001899 0.0373907951953854 -0.0208027427000385" rpy="0 0 0" />
        <mass value="0.022614240507152" />
        <inertia ixx="1.52518312458174E-05" ixy="9.76583423954399E-10" ixz="-5.43838577022588E-10" iyy="6.17694243867776E-06" iyz="6.78636130740228E-06" izz="1.16494917907219E-05" />
        </inertial> -->
    <visual>
      <origin rpy="0 0 0" xyz="0 0 0"/>
      <geometry>
        <mesh filename="package://uniform_object_rearrangement/urdf/robotiq_85/visual/robotiq_arg2f_85_outer_finger.dae" scale="0.001 0.001 0.001"/>
      </geometry>
      <material name="">
        <color rgba="0.1 0.1 0.1 1"/>
      </material>
    </visual>
    <collision>
      <origin rpy="0 0 0" xyz="0 0 0"/>
      <geometry>
        <mesh filename="package://uniform_object_rearrangement/urdf/robotiq_85/collision/robotiq_arg2f_85_outer_finger.dae" scale="0.001 0.001 0.001"/>
      </geometry>
    </collision>
  </link>
  <link name="left_inner_finger">
    <!--<inertial>
        <origin xyz="0.000299999999999317 0.0160078233491243 -0.0136945669206257" rpy="0 0 0" />
        <mass value="0.0104003125914103" />
        <inertia ixx="2.71909453810972E-06" ixy="1.35402465472579E-21" ixz="-7.1817349065269E-22" iyy="7.69100314106116E-07" iyz="6.74715432769696E-07" izz="2.30315190420171E-06" />
        </inertial> -->
    <visual>
      <origin rpy="0 0 0" xyz="0 0 0"/>
      <geometry>
        <mesh filename="package://uniform_object_rearrangement/urdf/robotiq_85/visual/robotiq_arg2f_85_inner_finger.dae" scale="0.001 0.001 0.001"/>
      </geometry>
      <material name="">
        <color rgba="0.1 0.1 0.1 1"/>
      </material>
    </visual>
    <collision>
      <origin rpy="0 0 0" xyz="0 0 0"/>
      <geometry>
        <mesh filename="package://uniform_object_rearrangement/urdf/robotiq_85/collision/robotiq_arg2f_85_inner_finger.dae" scale="0.001 0.001 0.001"/>
      </geometry>
    </collision>
  </link>
  <link name="left_inner_finger_pad">
    <visual>
      <origin rpy="0 0 0" xyz="0 0 0"/>
      <geometry>
        <box size="0.022 0.00635 0.0375"/>
      </geometry>
      <material name="">
        <color rgba="0.9 0.9 0.9 1"/>
      </material>
    </visual>
    <collision>
      <origin rpy="0 0 0" xyz="0 0 0"/>
      <geometry>
        <box size="0.022 0.00635 0.0375"/>
      </geometry>
      <material name="">
        <color rgba="0.9 0.0 0.0 1"/>
      </material>
    </collision>
  </link>
  <link name="left_inner_knuckle">
    <!--<inertial>
        <origin xyz="0.000123011831763771 0.0507850843201817 0.00103968640075166" rpy="0 0 0" />
       <mass value="0.0271177346495152" />
        <inertia ixx="2.61910379223783E-05" ixy="-2.43616858946494E-07" ixz="-6.37789906117123E-09" iyy="2.8270243746167E-06" iyz="-5.37200748039765E-07" izz="2.83695868220296E-05" />
        </inertial> -->
    <visual>
      <origin rpy="0 0 0" xyz="0 0 0"/>
      <geometry>
        <mesh filename="package://uniform_object_rearrangement/urdf/robotiq_85/visual/robotiq_arg2f_85_inner_knuckle.dae" scale="0.001 0.001 0.001"/>
      </geometry>
      <material name="">
        <color rgba="0.1 0.1 0.1 1"/>
      </material>
    </visual>
    <collision>
      <origin rpy="0 0 0" xyz="0 0 0"/>
      <geometry>
        <mesh filename="package://uniform_object_rearrangement/urdf/robotiq_85/collision/robotiq_arg2f_85_inner_knuckle.dae" scale="0.001 0.001 0.001"/>
      </geometry>
    </collision>
  </link>
  <link name="right_outer_knuckle">
    <!--<inertial>
        <origin xyz="-0.000200000000003065 0.0199435877845359 0.0292245259211331" rpy="0 0 0" />
        <mass value="0.00853198276973456" />
        <inertia ixx="2.89328108496468E-06" ixy="-1.57935047237397E-19" ixz="-1.93980378593255E-19" iyy="1.86719750325683E-06" iyz="-1.21858577871576E-06" izz="1.21905238907251E-06" />
        </inertial> -->
    <visual>
      <origin rpy="0 0 0" xyz="0 0 0"/>
      <geometry>
        <mesh filename="package://uniform_object_rearrangement/urdf/robotiq_85/visual/robotiq_arg2f_85_outer_knuckle.dae" scale="0.001 0.001 0.001"/>
      </geometry>
      <material name="">
        <color rgba="0.792156862745098 0.819607843137255 0.933333333333333 1"/>
      </material>
    </visual>
    <collision>
      <origin rpy="0 0 0" xyz="0 0 0"/>
      <geometry>
        <mesh filename="package://uniform_object_rearrangement/urdf/robotiq_85/collision/robotiq_arg2f_85_outer_knuckle.dae" scale="0.001 0.001 0.001"/>
      </geometry>
    </collision>
  </link>
  <link name="right_outer_finger">
    <!--<inertial>
        <origin xyz="0.00030115855001899 0.0373907951953854 -0.0208027427000385" rpy="0 0 0" />
        <mass value="0.022614240507152" />
        <inertia ixx="1.52518312458174E-05" ixy="9.76583423954399E-10" ixz="-5.43838577022588E-10" iyy="6.17694243867776E-06" iyz="6.78636130740228E-06" izz="1.16494917907219E-05" />
        </inertial> -->
    <visual>
      <origin rpy="0 0 0" xyz="0 0 0"/>
      <geometry>
        <mesh filename="package://uniform_object_rearrangement/urdf/robotiq_85/visual/robotiq_arg2f_85_outer_finger.dae" scale="0.001 0.001 0.001"/>
      </geometry>
      <material name="">
        <color rgba="0.1 0.1 0.1 1"/>
      </material>
    </visual>
    <collision>
      <origin rpy="0 0 0" xyz="0 0 0"/>
      <geometry>
        <mesh filename="package://uniform_object_rearrangement/urdf/robotiq_85/collision/robotiq_arg2f_85_outer_finger.dae" scale="0.001 0.001 0.001"/>
      </geometry>
    </collision>
  </link>
  <link name="right_inner_finger">
    <!--<inertial>
        <origin xyz="0.000299999999999317 0.0160078233491243 -0.0136945669206257" rpy="0 0 0" />
        <mass value="0.0104003125914103" />
        <inertia ixx="2.71909453810972E-06" ixy="1.35402465472579E-21" ixz="-7.1817349065269E-22" iyy="7.69100314106116E-07" iyz="6.74715432769696E-07" izz="2.30315190420171E-06" />
        </inertial> -->
    <visual>
      <origin rpy="0 0 0" xyz="0 0 0"/>
      <geometry>
        <mesh filename="package://uniform_object_rearrangement/urdf/robotiq_85/visual/robotiq_arg2f_85_inner_finger.dae" scale="0.001 0.001 0.001"/>
      </geometry>
      <material name="">
        <color rgba="0.1 0.1 0.1 1"/>
      </material>
    </visual>
    <collision>
      <origin rpy="0 0 0" xyz="0 0 0"/>
      <geometry>
        <mesh filename="package://uniform_object_rearrangement/urdf/robotiq_85/collision/robotiq_arg2f_85_inner_finger.dae" scale="0.001 0.001 0.001"/>
      </geometry>
    </collision>
  </link>
  <link name="right_inner_finger_pad">
    <visual>
      <origin rpy="0 0 0" xyz="0 0 0"/>
      <geometry>
        <box size="0.022 0.00635 0.0375"/>
      </geometry>
      <material name="">
        <color rgba="0.9 0.9 0.9 1"/>
      </material>
    </visual>
    <collision>
      <origin rpy="0 0 0" xyz="0 0 0"/>
      <geometry>
        <box size="0.022 0.00635 0.0375"/>
      </geometry>
      <material name="">
        <color rgba="0.9 0.0 0.0 1"/>
      </material>
    </collision>
  </link>
  <link name="right_inner_knuckle">
    <!--<inertial>
        <origin xyz="0.000123011831763771 0.0507850843201817 0.00103968640075166" rpy="0 0 0" />
       <mass value="0.0271177346495152" />
        <inertia ixx="2.61910379223783E-05" ixy="-2.43616858946494E-07" ixz="-6.37789906117123E-09" iyy="2.8270243746167E-06" iyz="-5.37200748039765E-07" izz="2.83695868220296E-05" />
        </inertial> -->
    <visual>
      <origin rpy="0 0 0" xyz="0 0 0"/>
      <geometry>
        <mesh filename="package://uniform_object_rearrangement/urdf/robotiq_85/visual/robotiq_arg2f_85_inner_knuckle.dae" scale="0.001 0.001 0.001"/>
      </geometry>
      <material name="">
        <color rgba="0.1 0.1 0.1 1"/>
      </material>
    </visual>
    <collision>
      <origin rpy="0 0 0" xyz="0 0 0"/>
      <geometry>
        <mesh filename="package://uniform_object_rearrangement/urdf/robotiq_85/collision/robotiq_arg2f_85_inner_knuckle.dae" scale="0.001 0.001 0.001"/>
      </geometry>
    </collision>
  </link>
  <joint name="finger_joint" type="revolute">
    <origin rpy="0 0 3.14159265359" xyz="0 -0.0306011 0.054904"/>
    <parent link="robotiq_arg2f_base_link"/>
    <child link="left_outer_knuckle"/>
    <axis xyz="1 0 0"/>
    <limit effort="1000" lower="0" upper="0.8" velocity="2.0"/>
  </joint>
  <joint name="left_outer_finger_joint" type="fixed">
    <origin rpy="0 0 0" xyz="0 0.0315 -0.0041"/>
    <parent link="left_outer_knuckle"/>
    <child link="left_outer_finger"/>
    <axis xyz="1 0 0"/>
  </joint>
  <joint name="left_inner_knuckle_joint" type="revolute">
    <!-- <origin xyz="0 ${reflect * -0.0127} 0.06142" rpy="${pi / 2 + .725} 0 ${(reflect - 1) * pi / 2}" /> -->
    <origin rpy="0 0 3.14159265359" xyz="0 -0.0127 0.06142"/>
    <parent link="robotiq_arg2f_base_link"/>
    <child link="left_inner_knuckle"/>
    <axis xyz="1 0 0"/>
    <limit effort="1000" lower="0" upper="0.8757" velocity="2.0"/>
    <mimic joint="finger_joint" multiplier="1" offset="0"/>
  </joint>
  <joint name="left_inner_finger_joint" type="revolute">
    <origin rpy="0 0 0" xyz="0 0.0061 0.0471"/>
    <parent link="left_outer_finger"/>
    <child link="left_inner_finger"/>
    <axis xyz="1 0 0"/>
    <limit effort="1000" lower="-0.8757" upper="0" velocity="2.0"/>
    <mimic joint="finger_joint" multiplier="-1" offset="0"/>
  </joint>
  <joint name="left_inner_finger_pad_joint" type="fixed">
    <origin rpy="0 0 0" xyz="0 -0.0220203446692936 0.03242"/>
    <parent link="left_inner_finger"/>
    <child link="left_inner_finger_pad"/>
    <axis xyz="0 0 1"/>
  </joint>
  <joint name="right_outer_knuckle_joint" type="revolute">
    <origin rpy="0 0 0" xyz="0 0.0306011 0.054904"/>
    <parent link="robotiq_arg2f_base_link"/>
    <child link="right_outer_knuckle"/>
    <axis xyz="1 0 0"/>
    <limit effort="1000" lower="0" upper="0.81" velocity="2.0"/>
    <mimic joint="finger_joint" multiplier="1" offset="0"/>
  </joint>
  <joint name="right_outer_finger_joint" type="fixed">
    <origin rpy="0 0 0" xyz="0 0.0315 -0.0041"/>
    <parent link="right_outer_knuckle"/>
    <child link="right_outer_finger"/>
    <axis xyz="1 0 0"/>
  </joint>
  <joint name="right_inner_knuckle_joint" type="revolute">
    <!-- <origin xyz="0 ${reflect * -0.0127} 0.06142" rpy="${pi / 2 + .725} 0 ${(reflect - 1) * pi / 2}" /> -->
    <origin rpy="0 0 0.0" xyz="0 0.0127 0.06142"/>
    <parent link="robotiq_arg2f_base_link"/>
    <child link="right_inner_knuckle"/>
    <axis xyz="1 0 0"/>
    <limit effort="1000" lower="0" upper="0.8757" velocity="2.0"/>
    <mimic joint="finger_joint" multiplier="1" offset="0"/>
  </joint>
  <joint name="right_inner_finger_joint" type="revolute">
    <origin rpy="0 0 0" xyz="0 0.0061 0.0471"/>
    <parent link="right_outer_finger"/>
    <child link="right_inner_finger"/>
    <axis xyz="1 0 0"/>
    <limit effort="1000" lower="-0.8757" upper="0" velocity="2.0"/>
    <mimic joint="finger_joint" multiplier="-1" offset="0"/>
  </joint>
  <joint name="right_inner_finger_pad_joint" type="fixed">
    <origin rpy="0 0 0" xyz="0 -0.0220203446692936 0.03242"/>
    <parent link="right_inner_finger"/>
    <child link="right_inner_finger_pad"/>
    <axis xyz="0 0 1"/>
  </joint>
  <transmission name="finger_joint_trans">
    <type>transmission_interface/SimpleTransmission</type>
    <joint name="finger_joint">
      <hardwareInterface>PositionJointInterface</hardwareInterface>
    </joint>
    <actuator name="finger_joint_motor">
      <mechanicalReduction>1</mechanicalReduction>
    </actuator>
  </transmission>


</robot>
